Workbook

Sheet SuppData1_ClinicalData
A1: Supplementary Data 1: Clinical Data
A4: Patient_ID | B4: Disease | C4: Group | D4: FusionGeneatDiagnosis | E4: FusionGeneatRelapse | F4: Karyotype Diagnosis | G4: Karyotype R | H4: Infant/Child | I4: Age group | J4: Treatment_Protocol | K4: Survival | L4: Relapse Site | M4: Risk grouping | N4: SCT | O4: WGS | P4: WES | Q4: Targeted Sequencing | R4: Paired
A5: P15 | B5: B-ALL | C5: Remission | D5: KMT2A::MLLT3 | E5: na | F5: 47-48,XY,t(9;11)(p22;q23)+1-2mar | G5: na | H5: Child | I5: 1-5 years | J5: NOPHO 1992 | K5: Alive | L5: NA | M5: High | N5: No | O5: - | P5: - | Q5: Yes | R5: No
A6: P16 | B6: B-ALL | C6: Remission | D6: KMT2A::AFF1 | E6: na | F6: 46,XY,t(4;11)(q21;q23)[18]/46,XY[7] | G6: na | H6: Child | I6: 1-5 years | J6: Interfant -99 | K6: Alive | L6: NA | M6: Unknown | N6: No | O6: - | P6: - | Q6: Yes | R6: No
A7: P19 | B7: B-ALL | C7: Remission | D7: KMT2A::ACIN1 | E7: na | F7: 46,XX,ins(11;14)(q23;q?),-14,+mar.ish.del(9)(p21p21) | G7: na | H7: Child | I7: 1-5 years | J7: NOPHO 1992 | K7: Alive | L7: NA | M7: Intermediate | N7: No | O7: - | P7: - | Q7: Yes | R7: No
A8: P2 | B8: B-ALL | C8: Remission | D8: KMT2A::MLLT1 | E8: na | F8: 46,XX,t(11;19)(q23;p13)[14] | G8: na | H8: Infant | I8: > 6 months | J8: Interfant -99 | K8: Alive | L8: NA | M8: Unknown | N8: Yes | O8: - | P8: - | Q8: Yes | R8: No
A9: P26 | B9: B-ALL | C9: Remission | D9: KMT2A::MLLT1 | E9: na | F9: 46,XX,t(11;?19)(q23;?)/46,XX | G9: na | H9: Infant | I9: 3-6 months | J9: AML 2004 | K9: Alive | L9: NA | M9: High | N9: No | O9: - | P9: - | Q9: Yes | R9: No
A10: P29 | B10: B-ALL | C10: Remission | D10: KMT2A::MLLT3 | E10: na | F10: 46,XY,t(9;11)(p21;q23) | G10: na | H10: Infant | I10: < 3 months | J10: Interfant -06 | K10: Alive | L10: NA | M10: Medium | N10: No | O10: - | P10: - | Q10: Yes | R10: No
A11: P1 | B11: MPAL | C11: Remission | D11: KMT2A::MLLT10 | E11: na | F11: 46,XX,del(10)(p11),der(11)inv(11)(q13q23)del(11)(q13),der(14)t(11;14)(q13;q32)t(10;11)(?;q23)[14]/46,XX[11] | G11: na | H11: Infant | I11: < 3 months | J11: Interfant -99 | K11: Alive | L11: NA | M11: Unknown | N11: No | O11: - | P11: - | Q11: Yes | R11: No
A12: P123 | B12: B-ALL | C12: Very early | D12: KMT2A::EPS15 | E12: KMT2A::EPS15 | F12: 46,XX,t(1;11)(p32;q23)[21]/46,XX,[1] | G12: - | H12: Infant | I12: < 3 months | J12: Interfant -99 | K12: Passed | L12: BM | M12: High | N12: Unknown | O12: D-R1 | P12: D-R1 | Q12: No | R12: No
A13: P126 | B13: B-ALL | C13: Very early | D13: KMT2A::MLLT1 | E13: KMT2A::MLLT1 | F13: 46,XY,t(11;19)(q23;013.3)[7]/46XY[3] | G13: - | H13: Infant | I13: 3-6 months | J13: Interfant -06 | K13: Passed | L13: BM | M13: Medium | N13: Unknown | O13: D-R1 | P13: D-R1 | Q13: No | R13: No
A14: P127 | B14: B-ALL | C14: Very early | D14: KMT2A::AFF1 | E14: KMT2A::AFF1 | F14: 46,XX,t(4;11)(q21;q23)[13]/46,XX[2] | G14: - | H14: Infant | I14: < 3 months | J14: Interfant -06 | K14: Passed | L14: BM | M14: Medium | N14: Unknown | O14: R1 | P14: D-G-R1 | Q14: No | R14: Yes
A15: P128 | B15: B-ALL | C15: Very early | D15: KMT2A::MLLT3 | E15: KMT2A::MLLT3 | F15: 46,XX?t(9;11)(P21;q23)[1],ISHt(9;11)(P21;q23)(3'MLL+;5'MLL+,3'MLL-)[11]/46,XX[19],NUCISH(MLLX2)(5'MLLSEP3'MLLX1)[181/200] | G15: - | H15: Infant | I15: < 3 months | J15: Interfant -06 | K15: Passed | L15: BM | M15: Medium | N15: Unknown | O15: R1 | P15: R1 | Q15: No | R15: No
... A56: P59 | B56: AML | C56: Late | D56: KMT2A::MLLT3 | E56: KMT2A::MLLT3 | F56: 47,XY,t(9;11)(p21;q23),+der(9)t(9;11) | G56: - | H56: Child | I56: 5-10 years | J56: AML 2004 | K56: Alive | L56: BM | M56: Standard | N56: Yes | O56: - | P56: - | Q56: Yes | R56: No

Sheet SuppData2_WES&WGSCoverage
A1: Supplementary Data 2: WES & WGS Coverage
A3: Sample details | E3: Whole Genome Sequencing | N3: Whole Exome Sequencing
A4: Patient | B4: Sample | C4: Sample Type | D4: Sampling Year | E4: Reads | F4: Mapped | G4: NonDupMpd | H4: Mapped | I4: Duplicates | J4: Mean Coverage | K4: Median Coverage | L4: WGS Date | M4: Pipeline | N4: Reads | O4: Mapped | P4: NonDupMpd | Q4: Mapped | R4: Duplicates | S4: Mean Coverage | T4: Median Coverage | U4: WES date | V4: Pipeline
A5: P12 | B5: P12-d0 | C5: Diagnosis | D5: 2010 | E5: 1061627520 | F5: 1000600286 | G5: 775643045 | H5: 0.942515 | I5: 0.224822 | J5: 39 | K5: 40 | L5: 42485 | M5: PCGP | N5: 196098342 | O5: 186185098 | P5: 150465770 | Q5: 0.9494 | R5: 0.1918 | S5: 207 | T5: 188 | U5: 42114 | V5: PCGP
A6: P12 | B6: P12-d48 | C6: Germline | D6: 2010 | E6: 812321998 | F6: 768169196 | G6: 616802372 | H6: 0.945646 | I6: 0.197049 | J6: 31 | K6: 32 | L6: 42485 | M6: PCGP | N6: 177151574 | O6: 166610425 | P6: 113826180 | Q6: 0.9405 | R6: 0.3168 | S6: 145 | T6: 103 | U6: 42114 | V6: PCGP
A7: P12 | B7: P12-d175 | C7: Relapse1 | D7: 2011 | E7: na | F7: na | G7: na | H7: na | I7: na | J7: na | K7: na | L7: na | M7: na | N7: 239216864 | O7: 238777533 | P7: 207727597 | Q7: 0.9982 | R7: 0.13 | S7: 282 | T7: 275 | U7: 44782 | V7: CAB
A8: P11 | B8: P11-d0 | C8: Diagnosis | D8: 1997 | E8: 1005144556 | F8: 1003490826 | G8: 865621408 | H8: 0.9984 | I8: 0.1374 | J8: 42 | K8: 42 | L8: 44806 | M8: PCGP | N8: na | O8: na | P8: na | Q8: na | R8: na | S8: na | T8: na | U8: na | V8: na
A9: P11 | B9: P11-d82 | C9: Germline | D9: 1997 | E9: 805951316 | F9: 759391521 | G9: 606386193 | H9: 0.94223 | I9: 0.201484 | J9: 31 | K9: 32 | L9: 42485 | M9: PCGP | N9: 174676880 | O9: 165299531 | P9: 132771582 | Q9: 0.9463 | R9: 0.1968 | S9: 178 | T9: 162 | U9: 42114 | V9: PCGP
A10: P11 | B10: P11-d223 | C10: Relapse1 | D10: 1998 | E10: 805951316 | F10: 759391521 | G10: 606386193 | H10: 0.94223 | I10: 0.201484 | J10: 54 | K10: 53 | L10: 44720 | M10: PCGP | N10: 260360719 | O10: 259640494 | P10: 213022144 | Q10: 0.9972 | R10: 0.1795 | S10: 271 | T10: 263 | U10: 44782 | V10: PCGP
A11: P58 | B11: P58-d0 | C11: Diagnosis | D11: 2000 | E11: 1897233332 | F11: 1805968916 | G11: 728416697 | H11: 0.951896 | I11: 0.596662 | J11: 37 | K11: 38 | L11: 42485 | M11: PCGP | N11: 248099692 | O11: 225004404 | P11: 195915886 | Q11: 0.906911 | R11: 0.12928 | S11: 222 | T11: 206 | U11: 42542 | V11: PCGP
A12: P58 | B12: P58-d182 | C12: Germline | D12: 2001 | E12: 2022958176 | F12: 1933145002 | G12: 780939299 | H12: 0.955603 | I12: 0.596027 | J12: 39 | K12: 40 | L12: 42485 | M12: PCGP | N12: na | O12: na | P12: na | Q12: na | R12: na | S12: na | T12: na | U12: na | V12: na
A13: P58 | B13: P58-d391 | C13: Relapse1 | D13: 2001 | E13: 888972120 | F13: 827593253 | G13: 772644671 | H13: 0.931 | I13: 0.0664 | J13: 43 | K13: 41 | L13: 43755 | M13: PCGP | N13: 107846484 | O13: 100205854 | P13: 56536957 | Q13: 0.9292 | R13: 0.4358 | S13: 74 | T13: 51 | U13: 43858 | V13: PCGP
A14: P28 | B14: P28-d0 | C14: Diagnosis | D14: 2005 | E14: 858376954 | F14: 791707915 | G14: 666512533 | H14: 0.9223 | I14: 0.1581 | J14: 34 | K14: 34 | L14: 42380 | M14: PCGP | N14: 195657564 | O14: 180046912 | P14: 150558027 | Q14: 0.9202 | R14: 0.1638 | S14: 179 | T14: 168 | U14: 42657 | V14: PCGP
A15: P28 | B15: P28-d29 | C15: Germline | D15: 2005 | E15: 912231886 | F15: 846057068 | G15: 708481954 | H15: 0.927458 | I15: 0.162607 | J15: 36 | K15: 37 | L15: 42380 | M15: PCGP | N15: na | O15: na | P15: na | Q15: na | R15: na | S15: na | T15: na | U15: na | V15: na
A16: P28 | B16: P28-d208 | C16: Relapse1 | D16: 2006 | E16: 1038961676 | F16: 998848888 | G16: 650859243 | H16: 0.961391 | I16: 0.348391 | J16: 53 | K16: 45 | L16: 42380 | M16: PCGP | N16: 111783934 | O16: 103722909 | P16: 81152686 | Q16: 0.9279 | R16: 0.2176 | S16: 108 | T16: 90 | U16: 42657 | V16: PCGP
A17: P3 | B17: P3-d0 | C17: Diagnosis | D17: 2007 | E17: 3752732630 | F17: 3558684735 | G17: 2634027134 | H17: 0.948292 | I17: 0.259831 | J17: 128 | K17: 134 | L17: 42485 | M17: PCGP | N17: 505747240 | O17: 458556452 | P17: 337110311 | Q17: 0.906691 | R17: 0.264844 | S17: 365 | T17: 346 | U17: 41988 | V17: PCGP
A18: P3 | B18: P3-seq3G | C18: Germline | D18: 2008 | E18: 962735030 | F18: 920785347 | G18: 724891879 | H18: 0.956427 | I18: 0.212746 | J18: 38 | K18: 39 | L18: 42485 | M18: PCGP | N18: 962735030 | O18: 920785347 | P18: 88097940 | Q18: 0.9564 | R18: 0.2127 | S18: 82.2136 | T18: 68 | U18: 41988 | V18: PCGP
A19: P3 | B19: P3-d396 | C19: Relapse1 | D19: 2008 | E19: 899600282 | F19: 840403295 | G19: 539855449 | H19: 0.934196 | I19: 0.357623 | J19: 31 | K19: 30 | L19: 44806 | M19: PCGP | N19: 115770724 | O19: 109370978 | P19: 78988521 | Q19: 0.944721 | R19: 0.277793 | S19: 122 | T19: 108 | U19: 43413 | V19: PCGP
A20: P57 | B20: P57-d0 | C20: Diagnosis | D20: 2000 | E20: 1170427828 | F20: 1097183224 | G20: 883160943 | H20: 0.937421 | I20: 0.195065 | J20: 52 | K20: 49 | L20: 42485 | M20: PCGP | N20: 147162970 | O20: 132545524 | P20: 114918137 | Q20: 0.900672 | R20: 0.132991 | S20: 132 | T20: 120 | U20: 42542 | V20: PCGP
A21: P57 | B21: P57-d217 | C21: Germline | D21: 2001 | E21: 1083273812 | F21: 967289441 | G21: 635925970 | H21: 0.892932 | I21: 0.342569 | J21: 31 | K21: 31 | L21: 42913 | M21: PCGP | N21: na | O21: na | P21: na | Q21: na | R21: na | S21: na | T21: na | U21: na | V21: na
A22: P57 | B22: P57-d537 | C22: Relapse1 | D22: 2002 | E22: 1095265338 | F22: 1046423323 | G22: 830682834 | H22: 0.955406 | I22: 0.206169 | J22: 43 | K22: 44 | L22: 42485 | M22: PCGP | N22: 32067872 | O22: 30764533 | P22: 27256584 | Q22: 0.9594 | R22: 0.114 | S22: 42 | T22: 36 | U22: 43593 | V22: PCGP
A23: P47 | B23: P47-d0 | C23: Diagnosis | D23: 2009 | E23: 1226545696 | F23: 1170132235 | G23: 965358959 | H23: 0.954006 | I23: 0.175 | J23: 57 | K23: 59 | L23: 42485 | M23: PCGP | N23: na | O23: na | P23: na | Q23: na | R23: na | S23: na | T23: na | U23: na | V23: na
A24: P47 | B24: P47-d1134 | C24: Germline | D24: 2013 | E24: 1107846600 | F24: 1045283390 | G24: 867009736 | H24: 0.943527 | I24: 0.170551 | J24: 45 | K24: 46 | L24: 42485 | M24: PCGP | N24: na | O24: na | P24: na | Q24: na | R24: na | S24: na | T24: na | U24: na | V24: na
A25: P47 | B25: P47-d1024 | C25: Relapse1 | D25: 2012 | E25: 1145110538 | F25: 1093888694 | G25: 922226696 | H25: 0.9553 | I25: 0.1569 | J25: 49 | K25: 48 | L25: 44720 | M25: PCGP | N25: 288544280 | O25: 287721068 | P25: 224722764 | Q25: 0.9971 | R25: 0.219 | S25: 286 | T25: 275 | U25: 44782 | V25: PCGP
A26: P17 | B26: P17-d0 | C26: Diagnosis | D26: 2005 | E26: 1144998352 | F26: 1092259354 | G26: 920997262 | H26: 0.95394 | I26: 0.156796 | J26: 45 | K26: 46 | L26: 42536 | M26: PCGP | N26: 175468492 | O26: 166898810 | P26: 127044266 | Q26: 0.9512 | R26: 0.2388 | S26: 198 | T26: 181 | U26: 42122 | V26: PCGP
A27: P17 | B27: P17-d210 | C27: Germline | D27: 2005 | E27: 1189663264 | F27: 1141120026 | G27: 978758603 | H27: 0.959196 | I27: 0.142283 | J27: 50 | K27: 51 | L27: 42536 | M27: PCGP | N27: 155929650 | O27: 148621495 | P27: 113305335 | Q27: 0.9531 | R27: 0.2376 | S27: 161 | T27: 149 | U27: 42122 | V27: PCGP
A28: P17 | B28: P17-d470 | C28: Relapse1 | D28: 2006 | E28: 723428320 | F28: 648219298 | G28: 584687427 | H28: 0.896 | I28: 0.098 | J28: 44 | K28: 35 | L28: 43554 | M28: PCGP | N28: 31642148 | O28: 29875228 | P28: 25325577 | Q28: 0.9442 | R28: 0.1523 | S28: 43 | T28: 30 | U28: 43593 | V28: PCGP
A29: P69 | B29: P69-d0 | C29: Diagnosis | D29: 2008 | E29: 1922561988 | F29: 1834221588 | G29: 648760355 | H29: 0.954051 | I29: 0.646302 | J29: 31 | K29: 32 | L29: 42485 | M29: PCGP | N29: 74143990 | O29: 70562379 | P29: 65642519 | Q29: 0.951694 | R29: 0.0697236 | S29: 87 | T29: 78 | U29: 42552 | V29: PCGP
A30: P69 | B30: P69-d145 | C30: Germline | D30: 2008 | E30: 2320621484 | F30: 2206789642 | G30: 761889370 | H30: 0.950948 | I30: 0.654752 | J30: 36 | K30: 38 | L30: 42485 | M30: PCGP | N30: na | O30: na | P30: na | Q30: na | R30: na | S30: na | T30: na | U30: na | V30: na
A31: P69 | B31: P69-d385 | C31: Relapse1 | D31: 2009 | E31: 1076798850 | F31: 1001137699 | G31: 854082614 | H31: 0.929735 | I31: 0.146888 | J31: 41 | K31: 42 | L31: 42809 | M31: PCGP | N31: 174475156 | O31: 147039217 | P31: 128626185 | Q31: 0.842752 | R31: 0.125225 | S31: 151 | T31: 139 | U31: 42825 | V31: PCGP
A32: P23 | B32: P23-d0 | C32: Diagnosis | D32: 2006 | E32: 1048096776 | F32: 1006033352 | G32: 899868630 | H32: 0.9599 | I32: 0.1055 | J32: 48 | K32: 48 | L32: 44305 | M32: PCGP | N32: 232967182 | O32: 221686236 | P32: 154592815 | Q32: 0.9516 | R32: 0.3027 | S32: 241 | T32: 223 | U32: 42126 | V32: PCGP
A33: P23 | B33: P23-d22 | C33: Germline | D33: 2006 | E33: 950514146 | F33: 909801375 | G33: 760284636 | H33: 0.9572 | I33: 0.1643 | J33: 38 | K33: 38 | L33: 44305 | M33: PCGP | N33: 142129444 | O33: 135631172 | P33: 96625043 | Q33: 0.9543 | R33: 0.2876 | S33: 139 | T33: 129 | U33: 42126 | V33: PCGP
A34: P23 | B34: P23-d103 | C34: Relapse1 | D34: 2006 | E34: 1250556710 | F34: 1198434149 | G34: 1057961055 | H34: 0.9583 | I34: 0.1172 | J34: 55 | K34: 56 | L34: 44305 | M34: PCGP | N34: 183561438 | O34: 170450376 | P34: 138007793 | Q34: 0.928574 | R34: 0.190334 | S34: 198 | T34: 186 | U34: 42657 | V34: PCGP
A35: P24 | B35: P24-d0 | C35: Diagnosis | D35: 1999 | E35: 1031128954 | F35: 960112365 | G35: 797245830 | H35: 0.931127 | I35: 0.169633 | J35: 39 | K35: 39 | L35: 42809 | M35: PCGP | N35: 161979674 | O35: 154669435 | P35: 106789133 | Q35: 0.9549 | R35: 0.3096 | S35: 160 | T35: 149 | U35: 42126 | V35: PCGP
A36: P24 | B36: P24-d108 | C36: Germline | D36: 1999 | E36: 1049017510 | F36: 979965581 | G36: 841608238 | H36: 0.934175 | I36: 0.141186 | J36: 42 | K36: 43 | L36: 42809 | M36: PCGP | N36: 215561762 | O36: 205095857 | P36: 146399952 | Q36: 0.9514 | R36: 0.2862 | S36: 226 | T36: 209 | U36: 42126 | V36: PCGP
A37: P24 | B37: P24-d445 | C37: Relapse1 | D37: 2000 | E37: 920900710 | F37: 858676732 | G37: 793771114 | H37: 0.9324 | I37: 0.0756 | J37: 44 | K37: 43 | L37: 43755 | M37: PCGP | N37: 109817890 | O37: 102452950 | P37: 57729759 | Q37: 0.9329 | R37: 0.4365 | S37: 71 | T37: 50 | U37: 43858 | V37: PCGP
A38: P30 | B38: P30-d21 | C38: Other | D38: 2001 | E38: 991021388 | F38: 926231742 | G38: 743352515 | H38: 0.934623 | I38: 0.197444 | J38: 31 | K38: 30 | L38: 42809 | M38: PCGP | N38: 120605680 | O38: 110705174 | P38: 98031496 | Q38: 0.91791 | R38: 0.114481 | S38: 125 | T38: 115 | U38: 42825 | V38: PCGP
A39: P30 | B39: P30-d222 | C39: Germline | D39: 2002 | E39: 984595318 | F39: 932740221 | G39: 766916737 | H39: 0.947334 | I39: 0.177781 | J39: 36 | K39: 38 | L39: 42809 | M39: PCGP | N39: na | O39: na | P39: na | Q39: na | R39: na | S39: na | T39: na | U39: na | V39: na
A40: P30 | B40: P30-d1037 | C40: Relapse2 | D40: 2004 | E40: 834709288 | F40: 772993907 | G40: 715054019 | H40: 0.9261 | I40: 0.075 | J40: 39 | K40: 38 | L40: 43755 | M40: PCGP | N40: 100775020 | O40: 93437980 | P40: 54169734 | Q40: 0.9272 | R40: 0.4203 | S40: 70 | T40: 49 | U40: 43858 | V40: PCGP
A41: P30 | B41: P30-d1742 | C41: Relapse3 | D41: 2006 | E41: 834666156 | F41: 832510210 | G41: 640212538 | H41: 0.9974 | I41: 0.231 | J41: 31 | K41: 30 | L41: 44806 | M41: PCGP | N41: 241291904 | O41: 240943235 | P41: 206283046 | Q41: 0.9986 | R41: 0.1439 | S41: 277 | T41: 267 | U41: 44782 | V41: PCGP
...

Sheet SuppData3_MutationalandClonalP
A1: Supplementary Data 3: Mutations and Clonal Patterns
G3: Nonsynonymous | N3: Synonymous
A4: Patient | B4: Sample | C4: Sample type | D4: Disease | E4: Group | F4: Total coding mutations | G4: Total nonsynonymous | H4: missense | I4: nonsense | J4: splice | K4: Indel | L4: exon | M4: splice_region | N4: Total synonymous | O4: UTR_3 | P4: UTR_5 | Q4: silent | R4: Noncoding mutations | S4: Total mutations | T4: Relapse specific | U4: Structural variants | V4: Overlap | W4: Copy Number Alterations | X4: Clonal Pattern
A5: P3 | B5: P3-d0 | C5: Diagnosis | D5: B-ALL | E5: Early | F5: =G5+N5 -> 5 | G5: =SUM(H5:M5) -> 4 | H5: =COUNTIFS(SuppData4_SNVINDEL!$B:$B,SuppData3_MutationalandClonalP!$B5,SuppData4_SNVINDEL!$F:$F,SuppData3_MutationalandClonalP!H$4) -> 4 | I5: =COUNTIFS(SuppData4_SNVINDEL!$B:$B,SuppData3_MutationalandClonalP!$B5,SuppData4_SNVINDEL!$F:$F,SuppData3_MutationalandClonalP!I$4) -> 0 | J5: =COUNTIFS(SuppData4_SNVINDEL!$B:$B,SuppData3_MutationalandClonalP!$B5,SuppData4_SNVINDEL!$F:$F,SuppData3_MutationalandClonalP!J$4) -> 0 | K5: =COUNTIFS(SuppData4_SNVINDEL!$B:$B,SuppData3_MutationalandClonalP!$B5,SuppData4_SNVINDEL!$F:$F,SuppData3_MutationalandClonalP!K$4) -> 0 | L5: =COUNTIFS(SuppData4_SNVINDEL!$B:$B,SuppData3_MutationalandClonalP!$B5,SuppData4_SNVINDEL!$F:$F,SuppData3_MutationalandClonalP!L$4) -> 0 | M5: =COUNTIFS(SuppData4_SNVINDEL!$B:$B,SuppData3_MutationalandClonalP!$B5,SuppData4_SNVINDEL!$F:$F,SuppData3_MutationalandClonalP!M$4) -> 0 | N5: =SUM(O5:Q5) -> 1 | O5: =COUNTIFS(SuppData4_SNVINDEL!$B:$B,SuppData3_MutationalandClonalP!$B5,SuppData4_SNVINDEL!$F:$F,SuppData3_MutationalandClonalP!O$4) -> 1 | P5: =COUNTIFS(SuppData4_SNVINDEL!$B:$B,SuppData3_MutationalandClonalP!$B5,SuppData4_SNVINDEL!$F:$F,SuppData3_MutationalandClonalP!P$4) -> 0 | Q5: =COUNTIFS(SuppData4_SNVINDEL!$B:$B,SuppData3_MutationalandClonalP!$B5,SuppData4_SNVINDEL!$F:$F,SuppData3_MutationalandClonalP!Q$4) -> 0 | R5: 190 | S5: =IFERROR(R5+F5,F5) -> 195 | T5: na | U5: =COUNTIFS(SuppData6_SV!A:A,SuppData3_MutationalandClonalP!B5,SuppData6_SV!U:U,"<>Yes") -> 2 | V5: =COUNTIFS(SuppData6_SV!A:A,SuppData3_MutationalandClonalP!B5,SuppData6_SV!U:U,"Yes") -> 0 | W5: =COUNTIFS(SuppData5_CNA!C:C,SuppData3_MutationalandClonalP!B5,SuppData5_CNA!H:H,"<>none") -> 0 | X5: Single clone seed relapse†
A6: P3 | B6: P3-d396 | C6: Relapse1 | D6: B-ALL | E6: Early | F6: =G6+N6 -> 33 | G6: =SUM(H6:M6) -> 19 | H6: =COUNTIFS(SuppData4_SNVINDEL!$B:$B,SuppData3_MutationalandClonalP!$B6,SuppData4_SNVINDEL!$F:$F,SuppData3_MutationalandClonalP!H$4) -> 12 | I6: =COUNTIFS(SuppData4_SNVINDEL!$B:$B,SuppData3_MutationalandClonalP!$B6,SuppData4_SNVINDEL!$F:$F,SuppData3_MutationalandClonalP!I$4) -> 2 | J6: =COUNTIFS(SuppData4_SNVINDEL!$B:$B,SuppData3_MutationalandClonalP!$B6,SuppData4_SNVINDEL!$F:$F,SuppData3_MutationalandClonalP!J$4) -> 0 | K6: =COUNTIFS(SuppData4_SNVINDEL!$B:$B,SuppData3_MutationalandClonalP!$B6,SuppData4_SNVINDEL!$F:$F,SuppData3_MutationalandClonalP!K$4) -> 2 | L6: =COUNTIFS(SuppData4_SNVINDEL!$B:$B,SuppData3_MutationalandClonalP!$B6,SuppData4_SNVINDEL!$F:$F,SuppData3_MutationalandClonalP!L$4) -> 2 | M6: =COUNTIFS(SuppData4_SNVINDEL!$B:$B,SuppData3_MutationalandClonalP!$B6,SuppData4_SNVINDEL!$F:$F,SuppData3_MutationalandClonalP!M$4) -> 1 | N6: =SUM(O6:Q6) -> 14 | O6: =COUNTIFS(SuppData4_SNVINDEL!$B:$B,SuppData3_MutationalandClonalP!$B6,SuppData4_SNVINDEL!$F:$F,SuppData3_MutationalandClonalP!O$4) -> 10 | P6: =COUNTIFS(SuppData4_SNVINDEL!$B:$B,SuppData3_MutationalandClonalP!$B6,SuppData4_SNVINDEL!$F:$F,SuppData3_MutationalandClonalP!P$4) -> 1 | Q6: =COUNTIFS(SuppData4_SNVINDEL!$B:$B,SuppData3_MutationalandClonalP!$B6,SuppData4_SNVINDEL!$F:$F,SuppData3_MutationalandClonalP!Q$4) -> 3 | R6: 784 | S6: =IFERROR(R6+F6,F6) -> 817 | T6: 747 | U6: =COUNTIFS(SuppData6_SV!A:A,SuppData3_MutationalandClonalP!B6,SuppData6_SV!U:U,"<>Yes") -> 2 | V6: =COUNTIFS(SuppData6_SV!A:A,SuppData3_MutationalandClonalP!B6,SuppData6_SV!U:U,"Yes") -> 0 | W6: =COUNTIFS(SuppData5_CNA!C:C,SuppData3_MutationalandClonalP!B6,SuppData5_CNA!H:H,"<>none") -> 2
A7: P11 | B7: P11-d0 | C7: Diagnosis | D7: B-ALL | E7: Very early | F7: =G7+N7 -> 13 | G7: =SUM(H7:M7) -> 11 | H7: =COUNTIFS(SuppData4_SNVINDEL!$B:$B,SuppData3_MutationalandClonalP!$B7,SuppData4_SNVINDEL!$F:$F,SuppData3_MutationalandClonalP!H$4) -> 1 | I7: =COUNTIFS(SuppData4_SNVINDEL!$B:$B,SuppData3_MutationalandClonalP!$B7,SuppData4_SNVINDEL!$F:$F,SuppData3_MutationalandClonalP!I$4) -> 0 | J7: =COUNTIFS(SuppData4_SNVINDEL!$B:$B,SuppData3_MutationalandClonalP!$B7,SuppData4_SNVINDEL!$F:$F,SuppData3_MutationalandClonalP!J$4) -> 0 | K7: =COUNTIFS(SuppData4_SNVINDEL!$B:$B,SuppData3_MutationalandClonalP!$B7,SuppData4_SNVINDEL!$F:$F,SuppData3_MutationalandClonalP!K$4) -> 10 | L7: =COUNTIFS(SuppData4_SNVINDEL!$B:$B,SuppData3_MutationalandClonalP!$B7,SuppData4_SNVINDEL!$F:$F,SuppData3_MutationalandClonalP!L$4) -> 0 | M7: =COUNTIFS(SuppData4_SNVINDEL!$B:$B,SuppData3_MutationalandClonalP!$B7,SuppData4_SNVINDEL!$F:$F,SuppData3_MutationalandClonalP!M$4) -> 0 | N7: =SUM(O7:Q7) -> 2 | O7: =COUNTIFS(SuppData4_SNVINDEL!$B:$B,SuppData3_MutationalandClonalP!$B7,SuppData4_SNVINDEL!$F:$F,SuppData3_MutationalandClonalP!O$4) -> 1 | P7: =COUNTIFS(SuppData4_SNVINDEL!$B:$B,SuppData3_MutationalandClonalP!$B7,SuppData4_SNVINDEL!$F:$F,SuppData3_MutationalandClonalP!P$4) -> 0 | Q7: =COUNTIFS(SuppData4_SNVINDEL!$B:$B,SuppData3_MutationalandClonalP!$B7,SuppData4_SNVINDEL!$F:$F,SuppData3_MutationalandClonalP!Q$4) -> 1 | R7: 405 | S7: =IFERROR(R7+F7,F7) -> 418 | T7: na | U7: =COUNTIFS(SuppData6_SV!A:A,SuppData3_MutationalandClonalP!B7,SuppData6_SV!U:U,"<>Yes") -> 5 | V7: =COUNTIFS(SuppData6_SV!A:A,SuppData3_MutationalandClonalP!B7,SuppData6_SV!U:U,"Yes") -> 0 | W7: =COUNTIFS(SuppData5_CNA!C:C,SuppData3_MutationalandClonalP!B7,SuppData5_CNA!H:H,"<>none") -> 0 | X7: Mulitple clones seed relapse
A8: P11 | B8: P11-d223 | C8: Relapse1 | D8: B-ALL | E8: Very early | F8: =G8+N8 -> 158 | G8: =SUM(H8:M8) -> 78 | H8: =COUNTIFS(SuppData4_SNVINDEL!$B:$B,SuppData3_MutationalandClonalP!$B8,SuppData4_SNVINDEL!$F:$F,SuppData3_MutationalandClonalP!H$4) -> 59 | I8: =COUNTIFS(SuppData4_SNVINDEL!$B:$B,SuppData3_MutationalandClonalP!$B8,SuppData4_SNVINDEL!$F:$F,SuppData3_MutationalandClonalP!I$4) -> 3 | J8: =COUNTIFS(SuppData4_SNVINDEL!$B:$B,SuppData3_MutationalandClonalP!$B8,SuppData4_SNVINDEL!$F:$F,SuppData3_MutationalandClonalP!J$4) -> 3 | K8: =COUNTIFS(SuppData4_SNVINDEL!$B:$B,SuppData3_MutationalandClonalP!$B8,SuppData4_SNVINDEL!$F:$F,SuppData3_MutationalandClonalP!K$4) -> 4 | L8: =COUNTIFS(SuppData4_SNVINDEL!$B:$B,SuppData3_MutationalandClonalP!$B8,SuppData4_SNVINDEL!$F:$F,SuppData3_MutationalandClonalP!L$4) -> 2 | M8: =COUNTIFS(SuppData4_SNVINDEL!$B:$B,SuppData3_MutationalandClonalP!$B8,SuppData4_SNVINDEL!$F:$F,SuppData3_MutationalandClonalP!M$4) -> 7 | N8: =SUM(O8:Q8) -> 80 | O8: =COUNTIFS(SuppData4_SNVINDEL!$B:$B,SuppData3_MutationalandClonalP!$B8,SuppData4_SNVINDEL!$F:$F,SuppData3_MutationalandClonalP!O$4) -> 38 | P8: =COUNTIFS(SuppData4_SNVINDEL!$B:$B,SuppData3_MutationalandClonalP!$B8,SuppData4_SNVINDEL!$F:$F,SuppData3_MutationalandClonalP!P$4) -> 9 | Q8: =COUNTIFS(SuppData4_SNVINDEL!$B:$B,SuppData3_MutationalandClonalP!$B8,SuppData4_SNVINDEL!$F:$F,SuppData3_MutationalandClonalP!Q$4) -> 33 | R8: 6288 | S8: =IFERROR(R8+F8,F8) -> 6446 | T8: 6364 | U8: =COUNTIFS(SuppData6_SV!A:A,SuppData3_MutationalandClonalP!B8,SuppData6_SV!U:U,"<>Yes") -> 4 | V8: =COUNTIFS(SuppData6_SV!A:A,SuppData3_MutationalandClonalP!B8,SuppData6_SV!U:U,"Yes") -> 0 | W8: =COUNTIFS(SuppData5_CNA!C:C,SuppData3_MutationalandClonalP!B8,SuppData5_CNA!H:H,"<>none") -> 3
A9: P12 | B9: P12-d0 | C9: Diagnosis | D9: B-ALL | E9: Very early | F9: =G9+N9 -> 4 | G9: =SUM(H9:M9) -> 2 | H9: =COUNTIFS(SuppData4_SNVINDEL!$B:$B,SuppData3_MutationalandClonalP!$B9,SuppData4_SNVINDEL!$F:$F,SuppData3_MutationalandClonalP!H$4) -> 1 | I9: =COUNTIFS(SuppData4_SNVINDEL!$B:$B,SuppData3_MutationalandClonalP!$B9,SuppData4_SNVINDEL!$F:$F,SuppData3_MutationalandClonalP!I$4) -> 0 | J9: =COUNTIFS(SuppData4_SNVINDEL!$B:$B,SuppData3_MutationalandClonalP!$B9,SuppData4_SNVINDEL!$F:$F,SuppData3_MutationalandClonalP!J$4) -> 0 | K9: =COUNTIFS(SuppData4_SNVINDEL!$B:$B,SuppData3_MutationalandClonalP!$B9,SuppData4_SNVINDEL!$F:$F,SuppData3_MutationalandClonalP!K$4) -> 0 | L9: =COUNTIFS(SuppData4_SNVINDEL!$B:$B,SuppData3_MutationalandClonalP!$B9,SuppData4_SNVINDEL!$F:$F,SuppData3_MutationalandClonalP!L$4) -> 1 | M9: =COUNTIFS(SuppData4_SNVINDEL!$B:$B,SuppData3_MutationalandClonalP!$B9,SuppData4_SNVINDEL!$F:$F,SuppData3_MutationalandClonalP!M$4) -> 0 | N9: =SUM(O9:Q9) -> 2 | O9: =COUNTIFS(SuppData4_SNVINDEL!$B:$B,SuppData3_MutationalandClonalP!$B9,SuppData4_SNVINDEL!$F:$F,SuppData3_MutationalandClonalP!O$4) -> 1 | P9: =COUNTIFS(SuppData4_SNVINDEL!$B:$B,SuppData3_MutationalandClonalP!$B9,SuppData4_SNVINDEL!$F:$F,SuppData3_MutationalandClonalP!P$4) -> 0 | Q9: =COUNTIFS(SuppData4_SNVINDEL!$B:$B,SuppData3_MutationalandClonalP!$B9,SuppData4_SNVINDEL!$F:$F,SuppData3_MutationalandClonalP!Q$4) -> 1 | R9: 27 | S9: =IFERROR(R9+F9,F9) -> 31 | T9: na | U9: =COUNTIFS(SuppData6_SV!A:A,SuppData3_MutationalandClonalP!B9,SuppData6_SV!U:U,"<>Yes") -> 2 | V9: =COUNTIFS(SuppData6_SV!A:A,SuppData3_MutationalandClonalP!B9,SuppData6_SV!U:U,"Yes") -> 0 | W9: =COUNTIFS(SuppData5_CNA!C:C,SuppData3_MutationalandClonalP!B9,SuppData5_CNA!H:H,"<>none") -> 0
A10: P12 | B10: P12-d175 | C10: Relapse1 | D10: B-ALL | E10: Very early | F10: =G10+N10 -> 1 | G10: =SUM(H10:M10) -> 1 | H10: =COUNTIFS(SuppData4_SNVINDEL!$B:$B,SuppData3_MutationalandClonalP!$B10,SuppData4_SNVINDEL!$F:$F,SuppData3_MutationalandClonalP!H$4) -> 0 | I10: =COUNTIFS(SuppData4_SNVINDEL!$B:$B,SuppData3_MutationalandClonalP!$B10,SuppData4_SNVINDEL!$F:$F,SuppData3_MutationalandClonalP!I$4) -> 0 | J10: =COUNTIFS(SuppData4_SNVINDEL!$B:$B,SuppData3_MutationalandClonalP!$B10,SuppData4_SNVINDEL!$F:$F,SuppData3_MutationalandClonalP!J$4) -> 0 | K10: =COUNTIFS(SuppData4_SNVINDEL!$B:$B,SuppData3_MutationalandClonalP!$B10,SuppData4_SNVINDEL!$F:$F,SuppData3_MutationalandClonalP!K$4) -> 1 | L10: =COUNTIFS(SuppData4_SNVINDEL!$B:$B,SuppData3_MutationalandClonalP!$B10,SuppData4_SNVINDEL!$F:$F,SuppData3_MutationalandClonalP!L$4) -> 0 | M10: =COUNTIFS(SuppData4_SNVINDEL!$B:$B,SuppData3_MutationalandClonalP!$B10,SuppData4_SNVINDEL!$F:$F,SuppData3_MutationalandClonalP!M$4) -> 0 | N10: =SUM(O10:Q10) -> 0 | O10: =COUNTIFS(SuppData4_SNVINDEL!$B:$B,SuppData3_MutationalandClonalP!$B10,SuppData4_SNVINDEL!$F:$F,SuppData3_MutationalandClonalP!O$4) -> 0 | P10: =COUNTIFS(SuppData4_SNVINDEL!$B:$B,SuppData3_MutationalandClonalP!$B10,SuppData4_SNVINDEL!$F:$F,SuppData3_MutationalandClonalP!P$4) -> 0 | Q10: =COUNTIFS(SuppData4_SNVINDEL!$B:$B,SuppData3_MutationalandClonalP!$B10,SuppData4_SNVINDEL!$F:$F,SuppData3_MutationalandClonalP!Q$4) -> 0 | R10: na | S10: =IFERROR(R10+F10,F10) -> 1 | T10: na | U10: na | V10: na | W10: =COUNTIFS(SuppData5_CNA!C:C,SuppData3_MutationalandClonalP!B10,SuppData5_CNA!H:H,"<>none") -> 0
A11: P17 | B11: P17-d0 | C11: Diagnosis | D11: B-ALL | E11: Early | F11: =G11+N11 -> 8 | G11: =SUM(H11:M11) -> 3 | H11: =COUNTIFS(SuppData4_SNVINDEL!$B:$B,SuppData3_MutationalandClonalP!$B11,SuppData4_SNVINDEL!$F:$F,SuppData3_MutationalandClonalP!H$4) -> 3 | I11: =COUNTIFS(SuppData4_SNVINDEL!$B:$B,SuppData3_MutationalandClonalP!$B11,SuppData4_SNVINDEL!$F:$F,SuppData3_MutationalandClonalP!I$4) -> 0 | J11: =COUNTIFS(SuppData4_SNVINDEL!$B:$B,SuppData3_MutationalandClonalP!$B11,SuppData4_SNVINDEL!$F:$F,SuppData3_MutationalandClonalP!J$4) -> 0 | K11: =COUNTIFS(SuppData4_SNVINDEL!$B:$B,SuppData3_MutationalandClonalP!$B11,SuppData4_SNVINDEL!$F:$F,SuppData3_MutationalandClonalP!K$4) -> 0 | L11: =COUNTIFS(SuppData4_SNVINDEL!$B:$B,SuppData3_MutationalandClonalP!$B11,SuppData4_SNVINDEL!$F:$F,SuppData3_MutationalandClonalP!L$4) -> 0 | M11: =COUNTIFS(SuppData4_SNVINDEL!$B:$B,SuppData3_MutationalandClonalP!$B11,SuppData4_SNVINDEL!$F:$F,SuppData3_MutationalandClonalP!M$4) -> 0 | N11: =SUM(O11:Q11) -> 5 | O11: =COUNTIFS(SuppData4_SNVINDEL!$B:$B,SuppData3_MutationalandClonalP!$B11,SuppData4_SNVINDEL!$F:$F,SuppData3_MutationalandClonalP!O$4) -> 2 | P11: =COUNTIFS(SuppData4_SNVINDEL!$B:$B,SuppData3_MutationalandClonalP!$B11,SuppData4_SNVINDEL!$F:$F,SuppData3_MutationalandClonalP!P$4) -> 1 | Q11: =COUNTIFS(SuppData4_SNVINDEL!$B:$B,SuppData3_MutationalandClonalP!$B11,SuppData4_SNVINDEL!$F:$F,SuppData3_MutationalandClonalP!Q$4) -> 2 | R11: 248 | S11: =IFERROR(R11+F11,F11) -> 256 | T11: na | U11: =COUNTIFS(SuppData6_SV!A:A,SuppData3_MutationalandClonalP!B11,SuppData6_SV!U:U,"<>Yes") -> 4 | V11: =COUNTIFS(SuppData6_SV!A:A,SuppData3_MutationalandClonalP!B11,SuppData6_SV!U:U,"Yes") -> 0 | W11: =COUNTIFS(SuppData5_CNA!C:C,SuppData3_MutationalandClonalP!B11,SuppData5_CNA!H:H,"<>none") -> 0 | X11: Single clone seed relapse
A12: P17 | B12: P17-d470 | C12: Relapse1 | D12: B-ALL | E12: Early | F12: =G12+N12 -> 374 | G12: =SUM(H12:M12) -> 195 | H12: =COUNTIFS(SuppData4_SNVINDEL!$B:$B,SuppData3_MutationalandClonalP!$B12,SuppData4_SNVINDEL!$F:$F,SuppData3_MutationalandClonalP!H$4) -> 137 | I12: =COUNTIFS(SuppData4_SNVINDEL!$B:$B,SuppData3_MutationalandClonalP!$B12,SuppData4_SNVINDEL!$F:$F,SuppData3_MutationalandClonalP!I$4) -> 4 | J12: =COUNTIFS(SuppData4_SNVINDEL!$B:$B,SuppData3_MutationalandClonalP!$B12,SuppData4_SNVINDEL!$F:$F,SuppData3_MutationalandClonalP!J$4) -> 8 | K12: =COUNTIFS(SuppData4_SNVINDEL!$B:$B,SuppData3_MutationalandClonalP!$B12,SuppData4_SNVINDEL!$F:$F,SuppData3_MutationalandClonalP!K$4) -> 13 | L12: =COUNTIFS(SuppData4_SNVINDEL!$B:$B,SuppData3_MutationalandClonalP!$B12,SuppData4_SNVINDEL!$F:$F,SuppData3_MutationalandClonalP!L$4) -> 18 | M12: =COUNTIFS(SuppData4_SNVINDEL!$B:$B,SuppData3_MutationalandClonalP!$B12,SuppData4_SNVINDEL!$F:$F,SuppData3_MutationalandClonalP!M$4) -> 15 | N12: =SUM(O12:Q12) -> 179 | O12: =COUNTIFS(SuppData4_SNVINDEL!$B:$B,SuppData3_MutationalandClonalP!$B12,SuppData4_SNVINDEL!$F:$F,SuppData3_MutationalandClonalP!O$4) -> 94 | P12: =COUNTIFS(SuppData4_SNVINDEL!$B:$B,SuppData3_MutationalandClonalP!$B12,SuppData4_SNVINDEL!$F:$F,SuppData3_MutationalandClonalP!P$4) -> 11 | Q12: =COUNTIFS(SuppData4_SNVINDEL!$B:$B,SuppData3_MutationalandClonalP!$B12,SuppData4_SNVINDEL!$F:$F,SuppData3_MutationalandClonalP!Q$4) -> 74 | R12: 6102 | S12: =IFERROR(R12+F12,F12) -> 6476 | T12: 6012 | U12: =COUNTIFS(SuppData6_SV!A:A,SuppData3_MutationalandClonalP!B12,SuppData6_SV!U:U,"<>Yes") -> 6 | V12: =COUNTIFS(SuppData6_SV!A:A,SuppData3_MutationalandClonalP!B12,SuppData6_SV!U:U,"Yes") -> 0 | W12: =COUNTIFS(SuppData5_CNA!C:C,SuppData3_MutationalandClonalP!B12,SuppData5_CNA!H:H,"<>none") -> 2
A13: P23 | B13: P23-d0 | C13: Diagnosis | D13: AML | E13: Early | F13: =G13+N13 -> 15 | G13: =SUM(H13:M13) -> 11 | H13: =COUNTIFS(SuppData4_SNVINDEL!$B:$B,SuppData3_MutationalandClonalP!$B13,SuppData4_SNVINDEL!$F:$F,SuppData3_MutationalandClonalP!H$4) -> 6 | I13: =COUNTIFS(SuppData4_SNVINDEL!$B:$B,SuppData3_MutationalandClonalP!$B13,SuppData4_SNVINDEL!$F:$F,SuppData3_MutationalandClonalP!I$4) -> 2 | J13: =COUNTIFS(SuppData4_SNVINDEL!$B:$B,SuppData3_MutationalandClonalP!$B13,SuppData4_SNVINDEL!$F:$F,SuppData3_MutationalandClonalP!J$4) -> 0 | K13: =COUNTIFS(SuppData4_SNVINDEL!$B:$B,SuppData3_MutationalandClonalP!$B13,SuppData4_SNVINDEL!$F:$F,SuppData3_MutationalandClonalP!K$4) -> 2 | L13: =COUNTIFS(SuppData4_SNVINDEL!$B:$B,SuppData3_MutationalandClonalP!$B13,SuppData4_SNVINDEL!$F:$F,SuppData3_MutationalandClonalP!L$4) -> 1 | M13: =COUNTIFS(SuppData4_SNVINDEL!$B:$B,SuppData3_MutationalandClonalP!$B13,SuppData4_SNVINDEL!$F:$F,SuppData3_MutationalandClonalP!M$4) -> 0 | N13: =SUM(O13:Q13) -> 4 | O13: =COUNTIFS(SuppData4_SNVINDEL!$B:$B,SuppData3_MutationalandClonalP!$B13,SuppData4_SNVINDEL!$F:$F,SuppData3_MutationalandClonalP!O$4) -> 0 | P13: =COUNTIFS(SuppData4_SNVINDEL!$B:$B,SuppData3_MutationalandClonalP!$B13,SuppData4_SNVINDEL!$F:$F,SuppData3_MutationalandClonalP!P$4) -> 1 | Q13: =COUNTIFS(SuppData4_SNVINDEL!$B:$B,SuppData3_MutationalandClonalP!$B13,SuppData4_SNVINDEL!$F:$F,SuppData3_MutationalandClonalP!Q$4) -> 3 | R13: 115 | S13: =IFERROR(R13+F13,F13) -> 130 | T13: na | U13: =COUNTIFS(SuppData6_SV!A:A,SuppData3_MutationalandClonalP!B13,SuppData6_SV!U:U,"<>Yes") -> 12 | V13: =COUNTIFS(SuppData6_SV!A:A,SuppData3_MutationalandClonalP!B13,SuppData6_SV!U:U,"Yes") -> 0 | W13: =COUNTIFS(SuppData5_CNA!C:C,SuppData3_MutationalandClonalP!B13,SuppData5_CNA!H:H,"<>none") -> 8 | X13: Mulitple clones seed relapse
A14: P23 | B14: P23-d103 | C14: Relapse1 | D14: AML | E14: Early | F14: =G14+N14 -> 18 | G14: =SUM(H14:M14) -> 11 | H14: =COUNTIFS(SuppData4_SNVINDEL!$B:$B,SuppData3_MutationalandClonalP!$B14,SuppData4_SNVINDEL!$F:$F,SuppData3_MutationalandClonalP!H$4) -> 7 | I14: =COUNTIFS(SuppData4_SNVINDEL!$B:$B,SuppData3_MutationalandClonalP!$B14,SuppData4_SNVINDEL!$F:$F,SuppData3_MutationalandClonalP!I$4) -> 2 | J14: =COUNTIFS(SuppData4_SNVINDEL!$B:$B,SuppData3_MutationalandClonalP!$B14,SuppData4_SNVINDEL!$F:$F,SuppData3_MutationalandClonalP!J$4) -> 0 | K14: =COUNTIFS(SuppData4_SNVINDEL!$B:$B,SuppData3_MutationalandClonalP!$B14,SuppData4_SNVINDEL!$F:$F,SuppData3_MutationalandClonalP!K$4) -> 2 | L14: =COUNTIFS(SuppData4_SNVINDEL!$B:$B,SuppData3_MutationalandClonalP!$B14,SuppData4_SNVINDEL!$F:$F,SuppData3_MutationalandClonalP!L$4) -> 0 | M14: =COUNTIFS(SuppData4_SNVINDEL!$B:$B,SuppData3_MutationalandClonalP!$B14,SuppData4_SNVINDEL!$F:$F,SuppData3_MutationalandClonalP!M$4) -> 0 | N14: =SUM(O14:Q14) -> 7 | O14: =COUNTIFS(SuppData4_SNVINDEL!$B:$B,SuppData3_MutationalandClonalP!$B14,SuppData4_SNVINDEL!$F:$F,SuppData3_MutationalandClonalP!O$4) -> 0 | P14: =COUNTIFS(SuppData4_SNVINDEL!$B:$B,SuppData3_MutationalandClonalP!$B14,SuppData4_SNVINDEL!$F:$F,SuppData3_MutationalandClonalP!P$4) -> 0 | Q14: =COUNTIFS(SuppData4_SNVINDEL!$B:$B,SuppData3_MutationalandClonalP!$B14,SuppData4_SNVINDEL!$F:$F,SuppData3_MutationalandClonalP!Q$4) -> 7 | R14: 285 | S14: =IFERROR(R14+F14,F14) -> 303 | T14: 233 | U14: =COUNTIFS(SuppData6_SV!A:A,SuppData3_MutationalandClonalP!B14,SuppData6_SV!U:U,"<>Yes") -> 19 | V14: =COUNTIFS(SuppData6_SV!A:A,SuppData3_MutationalandClonalP!B14,SuppData6_SV!U:U,"Yes") -> 0 | W14: =COUNTIFS(SuppData5_CNA!C:C,SuppData3_MutationalandClonalP!B14,SuppData5_CNA!H:H,"<>none") -> 16
A15: P24 | B15: P24-d0 | C15: Diagnosis | D15: AML | E15: Late | F15: =G15+N15 -> 15 | G15: =SUM(H15:M15) -> 11 | H15: =COUNTIFS(SuppData4_SNVINDEL!$B:$B,SuppData3_MutationalandClonalP!$B15,SuppData4_SNVINDEL!$F:$F,SuppData3_MutationalandClonalP!H$4) -> 4 | I15: =COUNTIFS(SuppData4_SNVINDEL!$B:$B,SuppData3_MutationalandClonalP!$B15,SuppData4_SNVINDEL!$F:$F,SuppData3_MutationalandClonalP!I$4) -> 0 | J15: =COUNTIFS(SuppData4_SNVINDEL!$B:$B,SuppData3_MutationalandClonalP!$B15,SuppData4_SNVINDEL!$F:$F,SuppData3_MutationalandClonalP!J$4) -> 2 | K15: =COUNTIFS(SuppData4_SNVINDEL!$B:$B,SuppData3_MutationalandClonalP!$B15,SuppData4_SNVINDEL!$F:$F,SuppData3_MutationalandClonalP!K$4) -> 4 | L15: =COUNTIFS(SuppData4_SNVINDEL!$B:$B,SuppData3_MutationalandClonalP!$B15,SuppData4_SNVINDEL!$F:$F,SuppData3_MutationalandClonalP!L$4) -> 1 | M15: =COUNTIFS(SuppData4_SNVINDEL!$B:$B,SuppData3_MutationalandClonalP!$B15,SuppData4_SNVINDEL!$F:$F,SuppData3_MutationalandClonalP!M$4) -> 0 | N15: =SUM(O15:Q15) -> 4 | O15: =COUNTIFS(SuppData4_SNVINDEL!$B:$B,SuppData3_MutationalandClonalP!$B15,SuppData4_SNVINDEL!$F:$F,SuppData3_MutationalandClonalP!O$4) -> 0 | P15: =COUNTIFS(SuppData4_SNVINDEL!$B:$B,SuppData3_MutationalandClonalP!$B15,SuppData4_SNVINDEL!$F:$F,SuppData3_MutationalandClonalP!P$4) -> 0 | Q15: =COUNTIFS(SuppData4_SNVINDEL!$B:$B,SuppData3_MutationalandClonalP!$B15,SuppData4_SNVINDEL!$F:$F,SuppData3_MutationalandClonalP!Q$4) -> 4 | R15: 301 | S15: =IFERROR(R15+F15,F15) -> 316 | T15: na | U15: =COUNTIFS(SuppData6_SV!A:A,SuppData3_MutationalandClonalP!B15,SuppData6_SV!U:U,"<>Yes") -> 4 | V15: =COUNTIFS(SuppData6_SV!A:A,SuppData3_MutationalandClonalP!B15,SuppData6_SV!U:U,"Yes") -> 0 | W15: =COUNTIFS(SuppData5_CNA!C:C,SuppData3_MutationalandClonalP!B15,SuppData5_CNA!H:H,"<>none") -> 2 | X15: Single clone seed relapse†
A16: P24 | B16: P24-d445 | C16: Relapse1 | D16: AML | E16: Late | F16: =G16+N16 -> 16 | G16: =SUM(H16:M16) -> 12 | H16: =COUNTIFS(SuppData4_SNVINDEL!$B:$B,SuppData3_MutationalandClonalP!$B16,SuppData4_SNVINDEL!$F:$F,SuppData3_MutationalandClonalP!H$4) -> 8 | I16: =COUNTIFS(SuppData4_SNVINDEL!$B:$B,SuppData3_MutationalandClonalP!$B16,SuppData4_SNVINDEL!$F:$F,SuppData3_MutationalandClonalP!I$4) -> 0 | J16: =COUNTIFS(SuppData4_SNVINDEL!$B:$B,SuppData3_MutationalandClonalP!$B16,SuppData4_SNVINDEL!$F:$F,SuppData3_MutationalandClonalP!J$4) -> 0 | K16: =COUNTIFS(SuppData4_SNVINDEL!$B:$B,SuppData3_MutationalandClonalP!$B16,SuppData4_SNVINDEL!$F:$F,SuppData3_MutationalandClonalP!K$4) -> 2 | L16: =COUNTIFS(SuppData4_SNVINDEL!$B:$B,SuppData3_MutationalandClonalP!$B16,SuppData4_SNVINDEL!$F:$F,SuppData3_MutationalandClonalP!L$4) -> 1 | M16: =COUNTIFS(SuppData4_SNVINDEL!$B:$B,SuppData3_MutationalandClonalP!$B16,SuppData4_SNVINDEL!$F:$F,SuppData3_MutationalandClonalP!M$4) -> 1 | N16: =SUM(O16:Q16) -> 4 | O16: =COUNTIFS(SuppData4_SNVINDEL!$B:$B,SuppData3_MutationalandClonalP!$B16,SuppData4_SNVINDEL!$F:$F,SuppData3_MutationalandClonalP!O$4) -> 1 | P16: =COUNTIFS(SuppData4_SNVINDEL!$B:$B,SuppData3_MutationalandClonalP!$B16,SuppData4_SNVINDEL!$F:$F,SuppData3_MutationalandClonalP!P$4) -> 0 | Q16: =COUNTIFS(SuppData4_SNVINDEL!$B:$B,SuppData3_MutationalandClonalP!$B16,SuppData4_SNVINDEL!$F:$F,SuppData3_MutationalandClonalP!Q$4) -> 3 | R16: 309 | S16: =IFERROR(R16+F16,F16) -> 325 | T16: 232 | U16: =COUNTIFS(SuppData6_SV!A:A,SuppData3_MutationalandClonalP!B16,SuppData6_SV!U:U,"<>Yes") -> 6 | V16: =COUNTIFS(SuppData6_SV!A:A,SuppData3_MutationalandClonalP!B16,SuppData6_SV!U:U,"Yes") -> 0 | W16: =COUNTIFS(SuppData5_CNA!C:C,SuppData3_MutationalandClonalP!B16,SuppData5_CNA!H:H,"<>none") -> 2
A17: P28 | B17: P28-d0 | C17: Diagnosis | D17: B-ALL | E17: Very early/refractory | F17: =G17+N17 -> 7 | G17: =SUM(H17:M17) -> 1 | H17: =COUNTIFS(SuppData4_SNVINDEL!$B:$B,SuppData3_MutationalandClonalP!$B17,SuppData4_SNVINDEL!$F:$F,SuppData3_MutationalandClonalP!H$4) -> 1 | I17: =COUNTIFS(SuppData4_SNVINDEL!$B:$B,SuppData3_MutationalandClonalP!$B17,SuppData4_SNVINDEL!$F:$F,SuppData3_MutationalandClonalP!I$4) -> 0 | J17: =COUNTIFS(SuppData4_SNVINDEL!$B:$B,SuppData3_MutationalandClonalP!$B17,SuppData4_SNVINDEL!$F:$F,SuppData3_MutationalandClonalP!J$4) -> 0 | K17: =COUNTIFS(SuppData4_SNVINDEL!$B:$B,SuppData3_MutationalandClonalP!$B17,SuppData4_SNVINDEL!$F:$F,SuppData3_MutationalandClonalP!K$4) -> 0 | L17: =COUNTIFS(SuppData4_SNVINDEL!$B:$B,SuppData3_MutationalandClonalP!$B17,SuppData4_SNVINDEL!$F:$F,SuppData3_MutationalandClonalP!L$4) -> 0 | M17: =COUNTIFS(SuppData4_SNVINDEL!$B:$B,SuppData3_MutationalandClonalP!$B17,SuppData4_SNVINDEL!$F:$F,SuppData3_MutationalandClonalP!M$4) -> 0 | N17: =SUM(O17:Q17) -> 6 | O17: =COUNTIFS(SuppData4_SNVINDEL!$B:$B,SuppData3_MutationalandClonalP!$B17,SuppData4_SNVINDEL!$F:$F,SuppData3_MutationalandClonalP!O$4) -> 2 | P17: =COUNTIFS(SuppData4_SNVINDEL!$B:$B,SuppData3_MutationalandClonalP!$B17,SuppData4_SNVINDEL!$F:$F,SuppData3_MutationalandClonalP!P$4) -> 1 | Q17: =COUNTIFS(SuppData4_SNVINDEL!$B:$B,SuppData3_MutationalandClonalP!$B17,SuppData4_SNVINDEL!$F:$F,SuppData3_MutationalandClonalP!Q$4) -> 3 | R17: 184 | S17: =IFERROR(R17+F17,F17) -> 191 | T17: na | U17: =COUNTIFS(SuppData6_SV!A:A,SuppData3_MutationalandClonalP!B17,SuppData6_SV!U:U,"<>Yes") -> 2 | V17: =COUNTIFS(SuppData6_SV!A:A,SuppData3_MutationalandClonalP!B17,SuppData6_SV!U:U,"Yes") -> 0 | W17: =COUNTIFS(SuppData5_CNA!C:C,SuppData3_MutationalandClonalP!B17,SuppData5_CNA!H:H,"<>none") -> 0 | X17: Mulitple clones seed relapse
A18: P28 | B18: P28-d208 | C18: Relapse1 | D18: B-ALL | E18: Very early/refractory | F18: =G18+N18 -> 18 | G18: =SUM(H18:M18) -> 7 | H18: =COUNTIFS(SuppData4_SNVINDEL!$B:$B,SuppData3_MutationalandClonalP!$B18,SuppData4_SNVINDEL!$F:$F,SuppData3_MutationalandClonalP!H$4) -> 5 | I18: =COUNTIFS(SuppData4_SNVINDEL!$B:$B,SuppData3_MutationalandClonalP!$B18,SuppData4_SNVINDEL!$F:$F,SuppData3_MutationalandClonalP!I$4) -> 0 | J18: =COUNTIFS(SuppData4_SNVINDEL!$B:$B,SuppData3_MutationalandClonalP!$B18,SuppData4_SNVINDEL!$F:$F,SuppData3_MutationalandClonalP!J$4) -> 0 | K18: =COUNTIFS(SuppData4_SNVINDEL!$B:$B,SuppData3_MutationalandClonalP!$B18,SuppData4_SNVINDEL!$F:$F,SuppData3_MutationalandClonalP!K$4) -> 1 | L18: =COUNTIFS(SuppData4_SNVINDEL!$B:$B,SuppData3_MutationalandClonalP!$B18,SuppData4_SNVINDEL!$F:$F,SuppData3_MutationalandClonalP!L$4) -> 0 | M18: =COUNTIFS(SuppData4_SNVINDEL!$B:$B,SuppData3_MutationalandClonalP!$B18,SuppData4_SNVINDEL!$F:$F,SuppData3_MutationalandClonalP!M$4) -> 1 | N18: =SUM(O18:Q18) -> 11 | O18: =COUNTIFS(SuppData4_SNVINDEL!$B:$B,SuppData3_MutationalandClonalP!$B18,SuppData4_SNVINDEL!$F:$F,SuppData3_MutationalandClonalP!O$4) -> 5 | P18: =COUNTIFS(SuppData4_SNVINDEL!$B:$B,SuppData3_MutationalandClonalP!$B18,SuppData4_SNVINDEL!$F:$F,SuppData3_MutationalandClonalP!P$4) -> 1 | Q18: =COUNTIFS(SuppData4_SNVINDEL!$B:$B,SuppData3_MutationalandClonalP!$B18,SuppData4_SNVINDEL!$F:$F,SuppData3_MutationalandClonalP!Q$4) -> 5 | R18: 454 | S18: =IFERROR(R18+F18,F18) -> 472 | T18: 414 | U18: =COUNTIFS(SuppData6_SV!A:A,SuppData3_MutationalandClonalP!B18,SuppData6_SV!U:U,"<>Yes") -> 8 | V18: =COUNTIFS(SuppData6_SV!A:A,SuppData3_MutationalandClonalP!B18,SuppData6_SV!U:U,"Yes") -> 0 | W18: =COUNTIFS(SuppData5_CNA!C:C,SuppData3_MutationalandClonalP!B18,SuppData5_CNA!H:H,"<>none") -> 3
A19: P30 | B19: P30-d21 | C19: 21 days, ca 20-30% blasts | D19: AML | E19: Late | F19: =G19+N19 -> 0 | G19: =SUM(H19:M19) -> 0 | H19: =COUNTIFS(SuppData4_SNVINDEL!$B:$B,SuppData3_MutationalandClonalP!$B19,SuppData4_SNVINDEL!$F:$F,SuppData3_MutationalandClonalP!H$4) -> 0 | I19: =COUNTIFS(SuppData4_SNVINDEL!$B:$B,SuppData3_MutationalandClonalP!$B19,SuppData4_SNVINDEL!$F:$F,SuppData3_MutationalandClonalP!I$4) -> 0 | J19: =COUNTIFS(SuppData4_SNVINDEL!$B:$B,SuppData3_MutationalandClonalP!$B19,SuppData4_SNVINDEL!$F:$F,SuppData3_MutationalandClonalP!J$4) -> 0 | K19: =COUNTIFS(SuppData4_SNVINDEL!$B:$B,SuppData3_MutationalandClonalP!$B19,SuppData4_SNVINDEL!$F:$F,SuppData3_MutationalandClonalP!K$4) -> 0 | L19: =COUNTIFS(SuppData4_SNVINDEL!$B:$B,SuppData3_MutationalandClonalP!$B19,SuppData4_SNVINDEL!$F:$F,SuppData3_MutationalandClonalP!L$4) -> 0 | M19: =COUNTIFS(SuppData4_SNVINDEL!$B:$B,SuppData3_MutationalandClonalP!$B19,SuppData4_SNVINDEL!$F:$F,SuppData3_MutationalandClonalP!M$4) -> 0 | N19: =SUM(O19:Q19) -> 0 | O19: =COUNTIFS(SuppData4_SNVINDEL!$B:$B,SuppData3_MutationalandClonalP!$B19,SuppData4_SNVINDEL!$F:$F,SuppData3_MutationalandClonalP!O$4) -> 0 | P19: =COUNTIFS(SuppData4_SNVINDEL!$B:$B,SuppData3_MutationalandClonalP!$B19,SuppData4_SNVINDEL!$F:$F,SuppData3_MutationalandClonalP!P$4) -> 0 | Q19: =COUNTIFS(SuppData4_SNVINDEL!$B:$B,SuppData3_MutationalandClonalP!$B19,SuppData4_SNVINDEL!$F:$F,SuppData3_MutationalandClonalP!Q$4) -> 0 | R19: 21 | S19: =IFERROR(R19+F19,F19) -> 21 | T19: na | U19: =COUNTIFS(SuppData6_SV!A:A,SuppData3_MutationalandClonalP!B19,SuppData6_SV!U:U,"<>Yes") -> 2 | V19: =COUNTIFS(SuppData6_SV!A:A,SuppData3_MutationalandClonalP!B19,SuppData6_SV!U:U,"Yes") -> 0 | W19: =COUNTIFS(SuppData5_CNA!C:C,SuppData3_MutationalandClonalP!B19,SuppData5_CNA!H:H,"<>none") -> 0
A20: P30 | B20: P30-d400 | C20: Relapse1 | D20: AML | E20: Late | F20: =G20+N20 -> 18 | G20: =SUM(H20:M20) -> 13 | H20: =COUNTIFS(SuppData4_SNVINDEL!$B:$B,SuppData3_MutationalandClonalP!$B20,SuppData4_SNVINDEL!$F:$F,SuppData3_MutationalandClonalP!H$4) -> 5 | I20: =COUNTIFS(SuppData4_SNVINDEL!$B:$B,SuppData3_MutationalandClonalP!$B20,SuppData4_SNVINDEL!$F:$F,SuppData3_MutationalandClonalP!I$4) -> 0 | J20: =COUNTIFS(SuppData4_SNVINDEL!$B:$B,SuppData3_MutationalandClonalP!$B20,SuppData4_SNVINDEL!$F:$F,SuppData3_MutationalandClonalP!J$4) -> 0 | K20: =COUNTIFS(SuppData4_SNVINDEL!$B:$B,SuppData3_MutationalandClonalP!$B20,SuppData4_SNVINDEL!$F:$F,SuppData3_MutationalandClonalP!K$4) -> 7 | L20: =COUNTIFS(SuppData4_SNVINDEL!$B:$B,SuppData3_MutationalandClonalP!$B20,SuppData4_SNVINDEL!$F:$F,SuppData3_MutationalandClonalP!L$4) -> 0 | M20: =COUNTIFS(SuppData4_SNVINDEL!$B:$B,SuppData3_MutationalandClonalP!$B20,SuppData4_SNVINDEL!$F:$F,SuppData3_MutationalandClonalP!M$4) -> 1 | N20: =SUM(O20:Q20) -> 5 | O20: =COUNTIFS(SuppData4_SNVINDEL!$B:$B,SuppData3_MutationalandClonalP!$B20,SuppData4_SNVINDEL!$F:$F,SuppData3_MutationalandClonalP!O$4) -> 3 | P20: =COUNTIFS(SuppData4_SNVINDEL!$B:$B,SuppData3_MutationalandClonalP!$B20,SuppData4_SNVINDEL!$F:$F,SuppData3_MutationalandClonalP!P$4) -> 0 | Q20: =COUNTIFS(SuppData4_SNVINDEL!$B:$B,SuppData3_MutationalandClonalP!$B20,SuppData4_SNVINDEL!$F:$F,SuppData3_MutationalandClonalP!Q$4) -> 2 | R20: 844 | S20: =IFERROR(R20+F20,F20) -> 862 | T20: 835 | U20: =COUNTIFS(SuppData6_SV!A:A,SuppData3_MutationalandClonalP!B20,SuppData6_SV!U:U,"<>Yes") -> 4 | V20: =COUNTIFS(SuppData6_SV!A:A,SuppData3_MutationalandClonalP!B20,SuppData6_SV!U:U,"Yes") -> 0 | W20: =COUNTIFS(SuppData5_CNA!C:C,SuppData3_MutationalandClonalP!B20,SuppData5_CNA!H:H,"<>none") -> 7 | X20: Unassigned
A21: P30 | B21: P30-d1037 | C21: Relapse2 | D21: AML | E21: Late | F21: =G21+N21 -> 43 | G21: =SUM(H21:M21) -> 24 | H21: =COUNTIFS(SuppData4_SNVINDEL!$B:$B,SuppData3_MutationalandClonalP!$B21,SuppData4_SNVINDEL!$F:$F,SuppData3_MutationalandClonalP!H$4) -> 15 | I21: =COUNTIFS(SuppData4_SNVINDEL!$B:$B,SuppData3_MutationalandClonalP!$B21,SuppData4_SNVINDEL!$F:$F,SuppData3_MutationalandClonalP!I$4) -> 1 | J21: =COUNTIFS(SuppData4_SNVINDEL!$B:$B,SuppData3_MutationalandClonalP!$B21,SuppData4_SNVINDEL!$F:$F,SuppData3_MutationalandClonalP!J$4) -> 0 | K21: =COUNTIFS(SuppData4_SNVINDEL!$B:$B,SuppData3_MutationalandClonalP!$B21,SuppData4_SNVINDEL!$F:$F,SuppData3_MutationalandClonalP!K$4) -> 5 | L21: =COUNTIFS(SuppData4_SNVINDEL!$B:$B,SuppData3_MutationalandClonalP!$B21,SuppData4_SNVINDEL!$F:$F,SuppData3_MutationalandClonalP!L$4) -> 2 | M21: =COUNTIFS(SuppData4_SNVINDEL!$B:$B,SuppData3_MutationalandClonalP!$B21,SuppData4_SNVINDEL!$F:$F,SuppData3_MutationalandClonalP!M$4) -> 1 | N21: =SUM(O21:Q21) -> 19 | O21: =COUNTIFS(SuppData4_SNVINDEL!$B:$B,SuppData3_MutationalandClonalP!$B21,SuppData4_SNVINDEL!$F:$F,SuppData3_MutationalandClonalP!O$4) -> 10 | P21: =COUNTIFS(SuppData4_SNVINDEL!$B:$B,SuppData3_MutationalandClonalP!$B21,SuppData4_SNVINDEL!$F:$F,SuppData3_MutationalandClonalP!P$4) -> 1 | Q21: =COUNTIFS(SuppData4_SNVINDEL!$B:$B,SuppData3_MutationalandClonalP!$B21,SuppData4_SNVINDEL!$F:$F,SuppData3_MutationalandClonalP!Q$4) -> 8 | R21: 1649 | S21: =IFERROR(R21+F21,F21) -> 1692 | T21: na | U21: =COUNTIFS(SuppData6_SV!A:A,SuppData3_MutationalandClonalP!B21,SuppData6_SV!U:U,"<>Yes") -> 4 | V21: =COUNTIFS(SuppData6_SV!A:A,SuppData3_MutationalandClonalP!B21,SuppData6_SV!U:U,"Yes") -> 0 | W21: =COUNTIFS(SuppData5_CNA!C:C,SuppData3_MutationalandClonalP!B21,SuppData5_CNA!H:H,"<>none") -> 6
A22: P30 | B22: P30-d1742 | C22: Relapse3 | D22: AML | E22: Late | F22: =G22+N22 -> 55 | G22: =SUM(H22:M22) -> 24 | H22: =COUNTIFS(SuppData4_SNVINDEL!$B:$B,SuppData3_MutationalandClonalP!$B22,SuppData4_SNVINDEL!$F:$F,SuppData3_MutationalandClonalP!H$4) -> 15 | I22: =COUNTIFS(SuppData4_SNVINDEL!$B:$B,SuppData3_MutationalandClonalP!$B22,SuppData4_SNVINDEL!$F:$F,SuppData3_MutationalandClonalP!I$4) -> 0 | J22: =COUNTIFS(SuppData4_SNVINDEL!$B:$B,SuppData3_MutationalandClonalP!$B22,SuppData4_SNVINDEL!$F:$F,SuppData3_MutationalandClonalP!J$4) -> 1 | K22: =COUNTIFS(SuppData4_SNVINDEL!$B:$B,SuppData3_MutationalandClonalP!$B22,SuppData4_SNVINDEL!$F:$F,SuppData3_MutationalandClonalP!K$4) -> 5 | L22: =COUNTIFS(SuppData4_SNVINDEL!$B:$B,SuppData3_MutationalandClonalP!$B22,SuppData4_SNVINDEL!$F:$F,SuppData3_MutationalandClonalP!L$4) -> 0 | M22: =COUNTIFS(SuppData4_SNVINDEL!$B:$B,SuppData3_MutationalandClonalP!$B22,SuppData4_SNVINDEL!$F:$F,SuppData3_MutationalandClonalP!M$4) -> 3 | N22: =SUM(O22:Q22) -> 31 | O22: =COUNTIFS(SuppData4_SNVINDEL!$B:$B,SuppData3_MutationalandClonalP!$B22,SuppData4_SNVINDEL!$F:$F,SuppData3_MutationalandClonalP!O$4) -> 17 | P22: =COUNTIFS(SuppData4_SNVINDEL!$B:$B,SuppData3_MutationalandClonalP!$B22,SuppData4_SNVINDEL!$F:$F,SuppData3_MutationalandClonalP!P$4) -> 2 | Q22: =COUNTIFS(SuppData4_SNVINDEL!$B:$B,SuppData3_MutationalandClonalP!$B22,SuppData4_SNVINDEL!$F:$F,SuppData3_MutationalandClonalP!Q$4) -> 12 | R22: 1740 | S22: =IFERROR(R22+F22,F22) -> 1795 | T22: na | U22: =COUNTIFS(SuppData6_SV!A:A,SuppData3_MutationalandClonalP!B22,SuppData6_SV!U:U,"<>Yes") -> 3 | V22: =COUNTIFS(SuppData6_SV!A:A,SuppData3_MutationalandClonalP!B22,SuppData6_SV!U:U,"Yes") -> 0 | W22: =COUNTIFS(SuppData5_CNA!C:C,SuppData3_MutationalandClonalP!B22,SuppData5_CNA!H:H,"<>none") -> 6
A23: P30 | B23: P30-d2183 | C23: Relapse4 | D23: AML | E23: Late | F23: =G23+N23 -> 263 | G23: =SUM(H23:M23) -> 150 | H23: =COUNTIFS(SuppData4_SNVINDEL!$B:$B,SuppData3_MutationalandClonalP!$B23,SuppData4_SNVINDEL!$F:$F,SuppData3_MutationalandClonalP!H$4) -> 124 | I23: =COUNTIFS(SuppData4_SNVINDEL!$B:$B,SuppData3_MutationalandClonalP!$B23,SuppData4_SNVINDEL!$F:$F,SuppData3_MutationalandClonalP!I$4) -> 1 | J23: =COUNTIFS(SuppData4_SNVINDEL!$B:$B,SuppData3_MutationalandClonalP!$B23,SuppData4_SNVINDEL!$F:$F,SuppData3_MutationalandClonalP!J$4) -> 1 | K23: =COUNTIFS(SuppData4_SNVINDEL!$B:$B,SuppData3_MutationalandClonalP!$B23,SuppData4_SNVINDEL!$F:$F,SuppData3_MutationalandClonalP!K$4) -> 10 | L23: =COUNTIFS(SuppData4_SNVINDEL!$B:$B,SuppData3_MutationalandClonalP!$B23,SuppData4_SNVINDEL!$F:$F,SuppData3_MutationalandClonalP!L$4) -> 2 | M23: =COUNTIFS(SuppData4_SNVINDEL!$B:$B,SuppData3_MutationalandClonalP!$B23,SuppData4_SNVINDEL!$F:$F,SuppData3_MutationalandClonalP!M$4) -> 12 | N23: =SUM(O23:Q23) -> 113 | O23: =COUNTIFS(SuppData4_SNVINDEL!$B:$B,SuppData3_MutationalandClonalP!$B23,SuppData4_SNVINDEL!$F:$F,SuppData3_MutationalandClonalP!O$4) -> 48 | P23: =COUNTIFS(SuppData4_SNVINDEL!$B:$B,SuppData3_MutationalandClonalP!$B23,SuppData4_SNVINDEL!$F:$F,SuppData3_MutationalandClonalP!P$4) -> 7 | Q23: =COUNTIFS(SuppData4_SNVINDEL!$B:$B,SuppData3_MutationalandClonalP!$B23,SuppData4_SNVINDEL!$F:$F,SuppData3_MutationalandClonalP!Q$4) -> 58 | R23: 22078 | S23: =IFERROR(R23+F23,F23) -> 22341 | T23: na | U23: =COUNTIFS(SuppData6_SV!A:A,SuppData3_MutationalandClonalP!B23,SuppData6_SV!U:U,"<>Yes") -> 3 | V23: =COUNTIFS(SuppData6_SV!A:A,SuppData3_MutationalandClonalP!B23,SuppData6_SV!U:U,"Yes") -> 0 | W23: =COUNTIFS(SuppData5_CNA!C:C,SuppData3_MutationalandClonalP!B23,SuppData5_CNA!H:H,"<>none") -> 6
A24: P32 | B24: P32-d0 | C24: Diagnosis | D24: AML | E24: Late | F24: =G24+N24 -> 6 | G24: =SUM(H24:M24) -> 2 | H24: =COUNTIFS(SuppData4_SNVINDEL!$B:$B,SuppData3_MutationalandClonalP!$B24,SuppData4_SNVINDEL!$F:$F,SuppData3_MutationalandClonalP!H$4) -> 2 | I24: =COUNTIFS(SuppData4_SNVINDEL!$B:$B,SuppData3_MutationalandClonalP!$B24,SuppData4_SNVINDEL!$F:$F,SuppData3_MutationalandClonalP!I$4) -> 0 | J24: =COUNTIFS(SuppData4_SNVINDEL!$B:$B,SuppData3_MutationalandClonalP!$B24,SuppData4_SNVINDEL!$F:$F,SuppData3_MutationalandClonalP!J$4) -> 0 | K24: =COUNTIFS(SuppData4_SNVINDEL!$B:$B,SuppData3_MutationalandClonalP!$B24,SuppData4_SNVINDEL!$F:$F,SuppData3_MutationalandClonalP!K$4) -> 0 | L24: =COUNTIFS(SuppData4_SNVINDEL!$B:$B,SuppData3_MutationalandClonalP!$B24,SuppData4_SNVINDEL!$F:$F,SuppData3_MutationalandClonalP!L$4) -> 0 | M24: =COUNTIFS(SuppData4_SNVINDEL!$B:$B,SuppData3_MutationalandClonalP!$B24,SuppData4_SNVINDEL!$F:$F,SuppData3_MutationalandClonalP!M$4) -> 0 | N24: =SUM(O24:Q24) -> 4 | O24: =COUNTIFS(SuppData4_SNVINDEL!$B:$B,SuppData3_MutationalandClonalP!$B24,SuppData4_SNVINDEL!$F:$F,SuppData3_MutationalandClonalP!O$4) -> 1 | P24: =COUNTIFS(SuppData4_SNVINDEL!$B:$B,SuppData3_MutationalandClonalP!$B24,SuppData4_SNVINDEL!$F:$F,SuppData3_MutationalandClonalP!P$4) -> 1 | Q24: =COUNTIFS(SuppData4_SNVINDEL!$B:$B,SuppData3_MutationalandClonalP!$B24,SuppData4_SNVINDEL!$F:$F,SuppData3_MutationalandClonalP!Q$4) -> 2 | R24: 51 | S24: =IFERROR(R24+F24,F24) -> 57 | T24: na | U24: =COUNTIFS(SuppData6_SV!A:A,SuppData3_MutationalandClonalP!B24,SuppData6_SV!U:U,"<>Yes") -> 4 | V24: =COUNTIFS(SuppData6_SV!A:A,SuppData3_MutationalandClonalP!B24,SuppData6_SV!U:U,"Yes") -> 0 | W24: =COUNTIFS(SuppData5_CNA!C:C,SuppData3_MutationalandClonalP!B24,SuppData5_CNA!H:H,"<>none") -> 0 | X24: Mulitple clones seed relapse
A25: P32 | B25: P32-d683 | C25: Relapse1 | D25: AML | E25: Late | F25: =G25+N25 -> 17 | G25: =SUM(H25:M25) -> 5 | H25: =COUNTIFS(SuppData4_SNVINDEL!$B:$B,SuppData3_MutationalandClonalP!$B25,SuppData4_SNVINDEL!$F:$F,SuppData3_MutationalandClonalP!H$4) -> 4 | I25: =COUNTIFS(SuppData4_SNVINDEL!$B:$B,SuppData3_MutationalandClonalP!$B25,SuppData4_SNVINDEL!$F:$F,SuppData3_MutationalandClonalP!I$4) -> 0 | J25: =COUNTIFS(SuppData4_SNVINDEL!$B:$B,SuppData3_MutationalandClonalP!$B25,SuppData4_SNVINDEL!$F:$F,SuppData3_MutationalandClonalP!J$4) -> 0 | K25: =COUNTIFS(SuppData4_SNVINDEL!$B:$B,SuppData3_MutationalandClonalP!$B25,SuppData4_SNVINDEL!$F:$F,SuppData3_MutationalandClonalP!K$4) -> 1 | L25: =COUNTIFS(SuppData4_SNVINDEL!$B:$B,SuppData3_MutationalandClonalP!$B25,SuppData4_SNVINDEL!$F:$F,SuppData3_MutationalandClonalP!L$4) -> 0 | M25: =COUNTIFS(SuppData4_SNVINDEL!$B:$B,SuppData3_MutationalandClonalP!$B25,SuppData4_SNVINDEL!$F:$F,SuppData3_MutationalandClonalP!M$4) -> 0 | N25: =SUM(O25:Q25) -> 12 | O25: =COUNTIFS(SuppData4_SNVINDEL!$B:$B,SuppData3_MutationalandClonalP!$B25,SuppData4_SNVINDEL!$F:$F,SuppData3_MutationalandClonalP!O$4) -> 5 | P25: =COUNTIFS(SuppData4_SNVINDEL!$B:$B,SuppData3_MutationalandClonalP!$B25,SuppData4_SNVINDEL!$F:$F,SuppData3_MutationalandClonalP!P$4) -> 2 | Q25: =COUNTIFS(SuppData4_SNVINDEL!$B:$B,SuppData3_MutationalandClonalP!$B25,SuppData4_SNVINDEL!$F:$F,SuppData3_MutationalandClonalP!Q$4) -> 5 | R25: 225 | S25: =IFERROR(R25+F25,F25) -> 242 | T25: 213 | U25: =COUNTIFS(SuppData6_SV!A:A,SuppData3_MutationalandClonalP!B25,SuppData6_SV!U:U,"<>Yes") -> 5 | V25: =COUNTIFS(SuppData6_SV!A:A,SuppData3_MutationalandClonalP!B25,SuppData6_SV!U:U,"Yes") -> 0 | W25: =COUNTIFS(SuppData5_CNA!C:C,SuppData3_MutationalandClonalP!B25,SuppData5_CNA!H:H,"<>none") -> 1
A26: P47 | B26: P47-d0 | C26: Diagnosis | D26: B-ALL | E26: Early | F26: =G26+N26 -> 8 | G26: =SUM(H26:M26) -> 5 | H26: =COUNTIFS(SuppData4_SNVINDEL!$B:$B,SuppData3_MutationalandClonalP!$B26,SuppData4_SNVINDEL!$F:$F,SuppData3_MutationalandClonalP!H$4) -> 3 | I26: =COUNTIFS(SuppData4_SNVINDEL!$B:$B,SuppData3_MutationalandClonalP!$B26,SuppData4_SNVINDEL!$F:$F,SuppData3_MutationalandClonalP!I$4) -> 0 | J26: =COUNTIFS(SuppData4_SNVINDEL!$B:$B,SuppData3_MutationalandClonalP!$B26,SuppData4_SNVINDEL!$F:$F,SuppData3_MutationalandClonalP!J$4) -> 0 | K26: =COUNTIFS(SuppData4_SNVINDEL!$B:$B,SuppData3_MutationalandClonalP!$B26,SuppData4_SNVINDEL!$F:$F,SuppData3_MutationalandClonalP!K$4) -> 2 | L26: =COUNTIFS(SuppData4_SNVINDEL!$B:$B,SuppData3_MutationalandClonalP!$B26,SuppData4_SNVINDEL!$F:$F,SuppData3_MutationalandClonalP!L$4) -> 0 | M26: =COUNTIFS(SuppData4_SNVINDEL!$B:$B,SuppData3_MutationalandClonalP!$B26,SuppData4_SNVINDEL!$F:$F,SuppData3_MutationalandClonalP!M$4) -> 0 | N26: =SUM(O26:Q26) -> 3 | O26: =COUNTIFS(SuppData4_SNVINDEL!$B:$B,SuppData3_MutationalandClonalP!$B26,SuppData4_SNVINDEL!$F:$F,SuppData3_MutationalandClonalP!O$4) -> 1 | P26: =COUNTIFS(SuppData4_SNVINDEL!$B:$B,SuppData3_MutationalandClonalP!$B26,SuppData4_SNVINDEL!$F:$F,SuppData3_MutationalandClonalP!P$4) -> 0 | Q26: =COUNTIFS(SuppData4_SNVINDEL!$B:$B,SuppData3_MutationalandClonalP!$B26,SuppData4_SNVINDEL!$F:$F,SuppData3_MutationalandClonalP!Q$4) -> 2 | R26: 133 | S26: =IFERROR(R26+F26,F26) -> 141 | T26: na | U26: =COUNTIFS(SuppData6_SV!A:A,SuppData3_MutationalandClonalP!B26,SuppData6_SV!U:U,"<>Yes") -> 2 | V26: =COUNTIFS(SuppData6_SV!A:A,SuppData3_MutationalandClonalP!B26,SuppData6_SV!U:U,"Yes") -> 0 | W26: =COUNTIFS(SuppData5_CNA!C:C,SuppData3_MutationalandClonalP!B26,SuppData5_CNA!H:H,"<>none") -> 1 | X26: Single clone seed relapse†
A27: P47 | B27: P47-d1024 | C27: Relapse1 | D27: B-ALL | E27: Early | F27: =G27+N27 -> 45 | G27: =SUM(H27:M27) -> 23 | H27: =COUNTIFS(SuppData4_SNVINDEL!$B:$B,SuppData3_MutationalandClonalP!$B27,SuppData4_SNVINDEL!$F:$F,SuppData3_MutationalandClonalP!H$4) -> 19 | I27: =COUNTIFS(SuppData4_SNVINDEL!$B:$B,SuppData3_MutationalandClonalP!$B27,SuppData4_SNVINDEL!$F:$F,SuppData3_MutationalandClonalP!I$4) -> 0 | J27: =COUNTIFS(SuppData4_SNVINDEL!$B:$B,SuppData3_MutationalandClonalP!$B27,SuppData4_SNVINDEL!$F:$F,SuppData3_MutationalandClonalP!J$4) -> 0 | K27: =COUNTIFS(SuppData4_SNVINDEL!$B:$B,SuppData3_MutationalandClonalP!$B27,SuppData4_SNVINDEL!$F:$F,SuppData3_MutationalandClonalP!K$4) -> 1 | L27: =COUNTIFS(SuppData4_SNVINDEL!$B:$B,SuppData3_MutationalandClonalP!$B27,SuppData4_SNVINDEL!$F:$F,SuppData3_MutationalandClonalP!L$4) -> 1 | M27: =COUNTIFS(SuppData4_SNVINDEL!$B:$B,SuppData3_MutationalandClonalP!$B27,SuppData4_SNVINDEL!$F:$F,SuppData3_MutationalandClonalP!M$4) -> 2 | N27: =SUM(O27:Q27) -> 22 | O27: =COUNTIFS(SuppData4_SNVINDEL!$B:$B,SuppData3_MutationalandClonalP!$B27,SuppData4_SNVINDEL!$F:$F,SuppData3_MutationalandClonalP!O$4) -> 13 | P27: =COUNTIFS(SuppData4_SNVINDEL!$B:$B,SuppData3_MutationalandClonalP!$B27,SuppData4_SNVINDEL!$F:$F,SuppData3_MutationalandClonalP!P$4) -> 0 | Q27: =COUNTIFS(SuppData4_SNVINDEL!$B:$B,SuppData3_MutationalandClonalP!$B27,SuppData4_SNVINDEL!$F:$F,SuppData3_MutationalandClonalP!Q$4) -> 9 | R27: 1389 | S27: =IFERROR(R27+F27,F27) -> 1434 | T27: 1296 | U27: =COUNTIFS(SuppData6_SV!A:A,SuppData3_MutationalandClonalP!B27,SuppData6_SV!U:U,"<>Yes") -> 3 | V27: =COUNTIFS(SuppData6_SV!A:A,SuppData3_MutationalandClonalP!B27,SuppData6_SV!U:U,"Yes") -> 0 | W27: =COUNTIFS(SuppData5_CNA!C:C,SuppData3_MutationalandClonalP!B27,SuppData5_CNA!H:H,"<>none") -> 4
A28: P57 | B28: P57-d0 | C28: Diagnosis | D28: B-ALL | E28: Early | F28: =G28+N28 -> 0 | G28: =SUM(H28:M28) -> 0 | H28: =COUNTIFS(SuppData4_SNVINDEL!$B:$B,SuppData3_MutationalandClonalP!$B28,SuppData4_SNVINDEL!$F:$F,SuppData3_MutationalandClonalP!H$4) -> 0 | I28: =COUNTIFS(SuppData4_SNVINDEL!$B:$B,SuppData3_MutationalandClonalP!$B28,SuppData4_SNVINDEL!$F:$F,SuppData3_MutationalandClonalP!I$4) -> 0 | J28: =COUNTIFS(SuppData4_SNVINDEL!$B:$B,SuppData3_MutationalandClonalP!$B28,SuppData4_SNVINDEL!$F:$F,SuppData3_MutationalandClonalP!J$4) -> 0 | K28: =COUNTIFS(SuppData4_SNVINDEL!$B:$B,SuppData3_MutationalandClonalP!$B28,SuppData4_SNVINDEL!$F:$F,SuppData3_MutationalandClonalP!K$4) -> 0 | L28: =COUNTIFS(SuppData4_SNVINDEL!$B:$B,SuppData3_MutationalandClonalP!$B28,SuppData4_SNVINDEL!$F:$F,SuppData3_MutationalandClonalP!L$4) -> 0 | M28: =COUNTIFS(SuppData4_SNVINDEL!$B:$B,SuppData3_MutationalandClonalP!$B28,SuppData4_SNVINDEL!$F:$F,SuppData3_MutationalandClonalP!M$4) -> 0 | N28: =SUM(O28:Q28) -> 0 | O28: =COUNTIFS(SuppData4_SNVINDEL!$B:$B,SuppData3_MutationalandClonalP!$B28,SuppData4_SNVINDEL!$F:$F,SuppData3_MutationalandClonalP!O$4) -> 0 | P28: =COUNTIFS(SuppData4_SNVINDEL!$B:$B,SuppData3_MutationalandClonalP!$B28,SuppData4_SNVINDEL!$F:$F,SuppData3_MutationalandClonalP!P$4) -> 0 | Q28: =COUNTIFS(SuppData4_SNVINDEL!$B:$B,SuppData3_MutationalandClonalP!$B28,SuppData4_SNVINDEL!$F:$F,SuppData3_MutationalandClonalP!Q$4) -> 0 | R28: 72 | S28: =IFERROR(R28+F28,F28) -> 72 | T28: na | U28: =COUNTIFS(SuppData6_SV!A:A,SuppData3_MutationalandClonalP!B28,SuppData6_SV!U:U,"<>Yes") -> 2 | V28: =COUNTIFS(SuppData6_SV!A:A,SuppData3_MutationalandClonalP!B28,SuppData6_SV!U:U,"Yes") -> 0 | W28: =COUNTIFS(SuppData5_CNA!C:C,SuppData3_MutationalandClonalP!B28,SuppData5_CNA!H:H,"<>none") -> 1 | X28: Single clone seed relapse†
